Workbook

Sheet Collections
A1: FRESHCUT | B1: ADDITIONAL | D1: AMENDS | E1: CANCELLATION | M1: 252 | N1: 252 | O1: 504 | P1: 330 | Q1: 190 | R1: 290 | S1: 290 | T1: 125 | U1: 300 | V1: 210 | W1: 130 | X1: 320 | Y1: 220 | Z1: 190
S2: IFCO 4314 | T2: CHBA6425 | U2: CHBA3418 | V2: CHBA6416
A3: CUSTOMER | B3: Transport PO | C3: Transport cost - including Fuel surcharge | D3: COLLECTION DATE | E3: DELIVERY DATE | G3: COLLECTION DEPOT | H3: COLLECTION REFERENCE | I3: NWF CRATE PO NUMBER | J3: DELIVERY SITE | K3: Pallets | L3: Comments | M3: 35ALDEPS Type 186 | N3: 35ALDEPSDEEP Type 216 | O3: 35ALD HALF Type 504 | P3: 35MAXH | Q3: 35MAXN | R3: 35IF6420 | S3: 35IF4314 | T3: 35DEEP | U3: 35HALF | V3: 35SHAL | W3: 35JSDEEP | X3: 35JSHALF | Y3: 35JSSHAL | Z3: 35JSSTD
A4: ALDI | C4: =IFERROR(INDEX('SLH Fuel Surcharge'!$H$34:$BH$64,MATCH(Collections!G4,'SLH Fuel Surcharge'!$H$34:$H$64,0),MATCH(Collections!F4,'SLH Fuel Surcharge'!$H$34:$BH$34,0)),0) -> 0 | D4: 46313 | E4: 46314 | F4: =VLOOKUP(D4,'date summary'!A:B,2,FALSE) -> 30 | H4: 228950414 | I4: PO00508348 | J4: Selsey | K4: =M4/$M$1+$P4/$P$1+Q4/$Q$1+R4/$R$1+S4/$S$1+T4/$T$1+U4/$U$1+V4/$V$1+W4/$W$1+X4/$X$1+Y4/$Y$1+N4/252+O4/504+Z4/190 -> 33 | M4: 8316
A5: JS | B5: PO00508790 | C5: =IFERROR(INDEX('SLH Fuel Surcharge'!$H$34:$BH$64,MATCH(Collections!G5,'SLH Fuel Surcharge'!$H$34:$H$64,0),MATCH(Collections!F5,'SLH Fuel Surcharge'!$H$34:$BH$34,0)),0) -> 174.85118 | D5: 46313 | E5: 46314 | F5: =VLOOKUP(D5,'date summary'!A:B,2,FALSE) -> 30 | G5: Dartford | H5: NAT5464/377238 | I5: PO00508363 | J5: Runcton | K5: =M5/$M$1+$P5/$P$1+Q5/$Q$1+R5/$R$1+S5/$S$1+T5/$T$1+U5/$U$1+V5/$V$1+W5/$W$1+X5/$X$1+Y5/$Y$1+N5/252+O5/504+Z5/190 -> 22 | W5: 1300 | X5: 2880 | Y5: 660
A6: IFCO | B6: PO00508788 | C6: =IFERROR(INDEX('SLH Fuel Surcharge'!$H$34:$BH$64,MATCH(Collections!G6,'SLH Fuel Surcharge'!$H$34:$H$64,0),MATCH(Collections!F6,'SLH Fuel Surcharge'!$H$34:$BH$34,0)),0) -> 632.23488 | D6: 46313 | E6: 46314 | F6: =VLOOKUP(D6,'date summary'!A:B,2,FALSE) -> 30 | G6: IFCO Glasshoughton & Freshcut | H6: 285449584 | I6: PO00508701 | J6: Merston | K6: =M6/$M$1+$P6/$P$1+Q6/$Q$1+R6/$R$1+S6/$S$1+T6/$T$1+U6/$U$1+V6/$V$1+W6/$W$1+X6/$X$1+Y6/$Y$1+N6/252+O6/504+Z6/190 -> 20 | L6: *Freshcut delivery for 19/10 am* | V6: 4200 | AA6: 304218863
A7: IFCO | B7: PO00508789 | C7: =IFERROR(INDEX('SLH Fuel Surcharge'!$H$34:$BH$64,MATCH(Collections!G7,'SLH Fuel Surcharge'!$H$34:$H$64,0),MATCH(Collections!F7,'SLH Fuel Surcharge'!$H$34:$BH$34,0)),0) -> 571.70051 | D7: 46313 | E7: 46314 | F7: =VLOOKUP(D7,'date summary'!A:B,2,FALSE) -> 30 | G7: IFCO Glasshoughton | H7: 285449585 | I7: PO00508712 | J7: Selsey | K7: =M7/$M$1+$P7/$P$1+Q7/$Q$1+R7/$R$1+S7/$S$1+T7/$T$1+U7/$U$1+V7/$V$1+W7/$W$1+X7/$X$1+Y7/$Y$1+N7/252+O7/504+Z7/190 -> 26 | V7: 5460 | AA7: 304218890
A8: ALDI | C8: =IFERROR(INDEX('SLH Fuel Surcharge'!$H$34:$BH$64,MATCH(Collections!G8,'SLH Fuel Surcharge'!$H$34:$H$64,0),MATCH(Collections!F8,'SLH Fuel Surcharge'!$H$34:$BH$34,0)),0) -> 0 | D8: 46314 | E8: 46315 | F8: =VLOOKUP(D8,'date summary'!A:B,2,FALSE) -> 30 | H8: 228950437 | I8: PO00508349 | J8: Selsey | K8: =M8/$M$1+$P8/$P$1+Q8/$Q$1+R8/$R$1+S8/$S$1+T8/$T$1+U8/$U$1+V8/$V$1+W8/$W$1+X8/$X$1+Y8/$Y$1+N8/252+O8/504+Z8/190 -> 33 | M8: 8316
A9: ALDI | C9: =IFERROR(INDEX('SLH Fuel Surcharge'!$H$34:$BH$64,MATCH(Collections!G9,'SLH Fuel Surcharge'!$H$34:$H$64,0),MATCH(Collections!F9,'SLH Fuel Surcharge'!$H$34:$BH$34,0)),0) -> 0 | D9: 46314 | E9: 46315 | F9: =VLOOKUP(D9,'date summary'!A:B,2,FALSE) -> 30 | H9: 228950583 | I9: PO00508355 | J9: Merston / Runcton | K9: =M9/$M$1+$P9/$P$1+Q9/$Q$1+R9/$R$1+S9/$S$1+T9/$T$1+U9/$U$1+V9/$V$1+W9/$W$1+X9/$X$1+Y9/$Y$1+N9/252+O9/504+Z9/190 -> 33 | L9: Merston 13 plt / Runcton 20 plt | M9: 8316
A10: IFCO | B10: PO00508879 | C10: =IFERROR(INDEX('SLH Fuel Surcharge'!$H$34:$BH$64,MATCH(Collections!G10,'SLH Fuel Surcharge'!$H$34:$H$64,0),MATCH(Collections!F10,'SLH Fuel Surcharge'!$H$34:$BH$34,0)),0) -> 571.70051 | D10: 46314 | E10: 46315 | F10: =VLOOKUP(D10,'date summary'!A:B,2,FALSE) -> 30 | G10: IFCO Glasshoughton | H10: 285451891 | I10: PO00508709 | J10: Runcton | K10: =M10/$M$1+$P10/$P$1+Q10/$Q$1+R10/$R$1+S10/$S$1+T10/$T$1+U10/$U$1+V10/$V$1+W10/$W$1+X10/$X$1+Y10/$Y$1+N10/252+O10/504+Z10/190 -> 26 | U10: 3000 | V10: 3360 | AA10: 304218882
A11: ALDI | C11: =IFERROR(INDEX('SLH Fuel Surcharge'!$H$34:$BH$64,MATCH(Collections!G11,'SLH Fuel Surcharge'!$H$34:$H$64,0),MATCH(Collections!F11,'SLH Fuel Surcharge'!$H$34:$BH$34,0)),0) -> 0 | D11: 46314 | E11: 46315 | F11: =VLOOKUP(D11,'date summary'!A:B,2,FALSE) -> 30 | H11: 229006114 | I11: PO00508777 | J11: Selsey / Runcton | K11: =M11/$M$1+$P11/$P$1+Q11/$Q$1+R11/$R$1+S11/$S$1+T11/$T$1+U11/$U$1+V11/$V$1+W11/$W$1+X11/$X$1+Y11/$Y$1+N11/252+O11/504+Z11/190 -> 33 | L11: Runcton 20 plt / Selsey 13 plt | O11: 16632
A12: ALDI | C12: =IFERROR(INDEX('SLH Fuel Surcharge'!$H$34:$BH$64,MATCH(Collections!G12,'SLH Fuel Surcharge'!$H$34:$H$64,0),MATCH(Collections!F12,'SLH Fuel Surcharge'!$H$34:$BH$34,0)),0) -> 0 | D12: 46315 | E12: 46316 | F12: =VLOOKUP(D12,'date summary'!A:B,2,FALSE) -> 30 | H12: 228950456 | I12: PO00508350 | J12: Selsey | K12: =M12/$M$1+$P12/$P$1+Q12/$Q$1+R12/$R$1+S12/$S$1+T12/$T$1+U12/$U$1+V12/$V$1+W12/$W$1+X12/$X$1+Y12/$Y$1+N12/252+O12/504+Z12/190 -> 33 | M12: 8316
A13: ALDI | C13: =IFERROR(INDEX('SLH Fuel Surcharge'!$H$34:$BH$64,MATCH(Collections!G13,'SLH Fuel Surcharge'!$H$34:$H$64,0),MATCH(Collections!F13,'SLH Fuel Surcharge'!$H$34:$BH$34,0)),0) -> 0 | D13: 46315 | E13: 46316 | F13: =VLOOKUP(D13,'date summary'!A:B,2,FALSE) -> 30 | H13: 228950614 | I13: PO00508357 | J13: Merston / Runcton | K13: =M13/$M$1+$P13/$P$1+Q13/$Q$1+R13/$R$1+S13/$S$1+T13/$T$1+U13/$U$1+V13/$V$1+W13/$W$1+X13/$X$1+Y13/$Y$1+N13/252+O13/504+Z13/190 -> 33 | L13: Merston 13 plt / Runcton 20 plt | M13: 8316
A14: JS | B14: PO00508791 | C14: =IFERROR(INDEX('SLH Fuel Surcharge'!$H$34:$BH$64,MATCH(Collections!G14,'SLH Fuel Surcharge'!$H$34:$H$64,0),MATCH(Collections!F14,'SLH Fuel Surcharge'!$H$34:$BH$34,0)),0) -> 174.85118 | D14: 46315 | E14: 46316 | F14: =VLOOKUP(D14,'date summary'!A:B,2,FALSE) -> 30 | G14: Dartford | H14: NAT5464/377239 | I14: PO00508364 | J14: Runcton | K14: =M14/$M$1+$P14/$P$1+Q14/$Q$1+R14/$R$1+S14/$S$1+T14/$T$1+U14/$U$1+V14/$V$1+W14/$W$1+X14/$X$1+Y14/$Y$1+N14/252+O14/504+Z14/190 -> 26 | W14: 1820 | X14: 2880 | Y14: 660
A15: IFCO | B15: PO00508881 | C15: =IFERROR(INDEX('SLH Fuel Surcharge'!$H$34:$BH$64,MATCH(Collections!G15,'SLH Fuel Surcharge'!$H$34:$H$64,0),MATCH(Collections!F15,'SLH Fuel Surcharge'!$H$34:$BH$34,0)),0) -> 632.23488 | D15: 46315 | E15: 46316 | F15: =VLOOKUP(D15,'date summary'!A:B,2,FALSE) -> 30 | G15: IFCO Glasshoughton & Freshcut | H15: 285451931 | I15: PO00508702 | J15: Merston | K15: =M15/$M$1+$P15/$P$1+Q15/$Q$1+R15/$R$1+S15/$S$1+T15/$T$1+U15/$U$1+V15/$V$1+W15/$W$1+X15/$X$1+Y15/$Y$1+N15/252+O15/504+Z15/190 -> 20 | L15: *Freshcut delivery for 21/10 am* | V15: 4200 | AA15: 304218866
A16: IFCO | B16: PO00508882 | C16: =IFERROR(INDEX('SLH Fuel Surcharge'!$H$34:$BH$64,MATCH(Collections!G16,'SLH Fuel Surcharge'!$H$34:$H$64,0),MATCH(Collections!F16,'SLH Fuel Surcharge'!$H$34:$BH$34,0)),0) -> 571.70051 | D16: 46315 | E16: 46316 | F16: =VLOOKUP(D16,'date summary'!A:B,2,FALSE) -> 30 | G16: IFCO Glasshoughton | H16: 285451933 | I16: PO00508713 | J16: Selsey | K16: =M16/$M$1+$P16/$P$1+Q16/$Q$1+R16/$R$1+S16/$S$1+T16/$T$1+U16/$U$1+V16/$V$1+W16/$W$1+X16/$X$1+Y16/$Y$1+N16/252+O16/504+Z16/190 -> 26 | V16: 5460 | AA16: 304218892
A17: ALDI | C17: =IFERROR(INDEX('SLH Fuel Surcharge'!$H$34:$BH$64,MATCH(Collections!G17,'SLH Fuel Surcharge'!$H$34:$H$64,0),MATCH(Collections!F17,'SLH Fuel Surcharge'!$H$34:$BH$34,0)),0) -> 0 | D17: 46316 | E17: 46317 | F17: =VLOOKUP(D17,'date summary'!A:B,2,FALSE) -> 30 | H17: 228950473 | I17: PO00508351 | J17: Selsey | K17: =M17/$M$1+$P17/$P$1+Q17/$Q$1+R17/$R$1+S17/$S$1+T17/$T$1+U17/$U$1+V17/$V$1+W17/$W$1+X17/$X$1+Y17/$Y$1+N17/252+O17/504+Z17/190 -> 33 | M17: 8316
A18: JS | B18: PO00508792 | C18: =IFERROR(INDEX('SLH Fuel Surcharge'!$H$34:$BH$64,MATCH(Collections!G18,'SLH Fuel Surcharge'!$H$34:$H$64,0),MATCH(Collections!F18,'SLH Fuel Surcharge'!$H$34:$BH$34,0)),0) -> 174.85118 | D18: 46316 | E18: 46317 | F18: =VLOOKUP(D18,'date summary'!A:B,2,FALSE) -> 30 | G18: Dartford | H18: NAT5464/377242 | I18: PO00508367 | J18: Selsey | K18: =M18/$M$1+$P18/$P$1+Q18/$Q$1+R18/$R$1+S18/$S$1+T18/$T$1+U18/$U$1+V18/$V$1+W18/$W$1+X18/$X$1+Y18/$Y$1+N18/252+O18/504+Z18/190 -> 26 | X18: 1920 | Y18: 1100 | Z18: 2850
A19: IFCO | C19: =IFERROR(INDEX('SLH Fuel Surcharge'!$H$34:$BH$64,MATCH(Collections!G19,'SLH Fuel Surcharge'!$H$34:$H$64,0),MATCH(Collections!F19,'SLH Fuel Surcharge'!$H$34:$BH$34,0)),0) -> 0 | D19: 46316 | E19: 46317 | F19: =VLOOKUP(D19,'date summary'!A:B,2,FALSE) -> 30 | I19: PO00508710 | J19: Runcton | K19: =M19/$M$1+$P19/$P$1+Q19/$Q$1+R19/$R$1+S19/$S$1+T19/$T$1+U19/$U$1+V19/$V$1+W19/$W$1+X19/$X$1+Y19/$Y$1+N19/252+O19/504+Z19/190 -> 26 | U19: 3000 | V19: 3360 | AA19: 304218886
A20: ALDI | C20: =IFERROR(INDEX('SLH Fuel Surcharge'!$H$34:$BH$64,MATCH(Collections!G20,'SLH Fuel Surcharge'!$H$34:$H$64,0),MATCH(Collections!F20,'SLH Fuel Surcharge'!$H$34:$BH$34,0)),0) -> 0 | D20: 46317 | E20: 46318 | F20: =VLOOKUP(D20,'date summary'!A:B,2,FALSE) -> 30 | H20: 228950490 | I20: PO00508352 | J20: Selsey | K20: =M20/$M$1+$P20/$P$1+Q20/$Q$1+R20/$R$1+S20/$S$1+T20/$T$1+U20/$U$1+V20/$V$1+W20/$W$1+X20/$X$1+Y20/$Y$1+N20/252+O20/504+Z20/190 -> 33 | M20: 8316
A21: ALDI | C21: =IFERROR(INDEX('SLH Fuel Surcharge'!$H$34:$BH$64,MATCH(Collections!G21,'SLH Fuel Surcharge'!$H$34:$H$64,0),MATCH(Collections!F21,'SLH Fuel Surcharge'!$H$34:$BH$34,0)),0) -> 0 | D21: 46317 | E21: 46318 | F21: =VLOOKUP(D21,'date summary'!A:B,2,FALSE) -> 30 | H21: 228950631 | I21: PO00508358 | J21: Merston / Runcton | K21: =M21/$M$1+$P21/$P$1+Q21/$Q$1+R21/$R$1+S21/$S$1+T21/$T$1+U21/$U$1+V21/$V$1+W21/$W$1+X21/$X$1+Y21/$Y$1+N21/252+O21/504+Z21/190 -> 33 | L21: Merston 13 plt / Runcton 20 plt | M21: 8316
A22: ALDI | C22: =IFERROR(INDEX('SLH Fuel Surcharge'!$H$34:$BH$64,MATCH(Collections!G22,'SLH Fuel Surcharge'!$H$34:$H$64,0),MATCH(Collections!F22,'SLH Fuel Surcharge'!$H$34:$BH$34,0)),0) -> 0 | D22: 46317 | E22: 46318 | F22: =VLOOKUP(D22,'date summary'!A:B,2,FALSE) -> 30 | H22: 228950674 | I22: PO00508361 | J22: Selsey | K22: =M22/$M$1+$P22/$P$1+Q22/$Q$1+R22/$R$1+S22/$S$1+T22/$T$1+U22/$U$1+V22/$V$1+W22/$W$1+X22/$X$1+Y22/$Y$1+N22/252+O22/504+Z22/190 -> 33 | N22: 8316
A23: JS | B23: PO00508793 | C23: =IFERROR(INDEX('SLH Fuel Surcharge'!$H$34:$BH$64,MATCH(Collections!G23,'SLH Fuel Surcharge'!$H$34:$H$64,0),MATCH(Collections!F23,'SLH Fuel Surcharge'!$H$34:$BH$34,0)),0) -> 174.85118 | D23: 46317 | E23: 46318 | F23: =VLOOKUP(D23,'date summary'!A:B,2,FALSE) -> 30 | G23: Dartford | H23: NAT5464/377240 | I23: PO00508365 | J23: Runcton | K23: =M23/$M$1+$P23/$P$1+Q23/$Q$1+R23/$R$1+S23/$S$1+T23/$T$1+U23/$U$1+V23/$V$1+W23/$W$1+X23/$X$1+Y23/$Y$1+N23/252+O23/504+Z23/190 -> 26 | W23: 1820 | X23: 2880 | Y23: 660
A24: IFCO | C24: =IFERROR(INDEX('SLH Fuel Surcharge'!$H$34:$BH$64,MATCH(Collections!G24,'SLH Fuel Surcharge'!$H$34:$H$64,0),MATCH(Collections!F24,'SLH Fuel Surcharge'!$H$34:$BH$34,0)),0) -> 0 | D24: 46317 | E24: 46318 | F24: =VLOOKUP(D24,'date summary'!A:B,2,FALSE) -> 30 | I24: PO00508703 | J24: Merston | K24: =M24/$M$1+$P24/$P$1+Q24/$Q$1+R24/$R$1+S24/$S$1+T24/$T$1+U24/$U$1+V24/$V$1+W24/$W$1+X24/$X$1+Y24/$Y$1+N24/252+O24/504+Z24/190 -> 20 | L24: *Freshcut delivery for 23/10 am* | V24: 4200 | AA24: 304218868
A25: IFCO | C25: =IFERROR(INDEX('SLH Fuel Surcharge'!$H$34:$BH$64,MATCH(Collections!G25,'SLH Fuel Surcharge'!$H$34:$H$64,0),MATCH(Collections!F25,'SLH Fuel Surcharge'!$H$34:$BH$34,0)),0) -> 0 | D25: 46317 | E25: 46318 | F25: =VLOOKUP(D25,'date summary'!A:B,2,FALSE) -> 30 | I25: PO00508705 | J25: Selsey | K25: =M25/$M$1+$P25/$P$1+Q25/$Q$1+R25/$R$1+S25/$S$1+T25/$T$1+U25/$U$1+V25/$V$1+W25/$W$1+X25/$X$1+Y25/$Y$1+N25/252+O25/504+Z25/190 -> 19 | R25: 3770 | S25: 1740 | AA25: 304218878
A26: IFCO | C26: =IFERROR(INDEX('SLH Fuel Surcharge'!$H$34:$BH$64,MATCH(Collections!G26,'SLH Fuel Surcharge'!$H$34:$H$64,0),MATCH(Collections!F26,'SLH Fuel Surcharge'!$H$34:$BH$34,0)),0) -> 0 | D26: 46317 | E26: 46318 | F26: =VLOOKUP(D26,'date summary'!A:B,2,FALSE) -> 30 | I26: PO00508714 | J26: Selsey | K26: =M26/$M$1+$P26/$P$1+Q26/$Q$1+R26/$R$1+S26/$S$1+T26/$T$1+U26/$U$1+V26/$V$1+W26/$W$1+X26/$X$1+Y26/$Y$1+N26/252+O26/504+Z26/190 -> 26 | V26: 5460 | AA26: 304218895
A27: ALDI | C27: =IFERROR(INDEX('SLH Fuel Surcharge'!$H$34:$BH$64,MATCH(Collections!G27,'SLH Fuel Surcharge'!$H$34:$H$64,0),MATCH(Collections!F27,'SLH Fuel Surcharge'!$H$34:$BH$34,0)),0) -> 0 | D27: 46318 | E27: 46319 | F27: =VLOOKUP(D27,'date summary'!A:B,2,FALSE) -> 30 | H27: 228950506 | I27: PO00508353 | J27: Selsey | K27: =M27/$M$1+$P27/$P$1+Q27/$Q$1+R27/$R$1+S27/$S$1+T27/$T$1+U27/$U$1+V27/$V$1+W27/$W$1+X27/$X$1+Y27/$Y$1+N27/252+O27/504+Z27/190 -> 33 | M27: 8316
A28: ALDI | C28: =IFERROR(INDEX('SLH Fuel Surcharge'!$H$34:$BH$64,MATCH(Collections!G28,'SLH Fuel Surcharge'!$H$34:$H$64,0),MATCH(Collections!F28,'SLH Fuel Surcharge'!$H$34:$BH$34,0)),0) -> 0 | D28: 46318 | E28: 46319 | F28: =VLOOKUP(D28,'date summary'!A:B,2,FALSE) -> 30 | H28: 228950698 | I28: PO00508362 | J28: Selsey / Runcton | K28: =M28/$M$1+$P28/$P$1+Q28/$Q$1+R28/$R$1+S28/$S$1+T28/$T$1+U28/$U$1+V28/$V$1+W28/$W$1+X28/$X$1+Y28/$Y$1+N28/252+O28/504+Z28/190 -> 33 | L28: Selsey 17 plt / Runcton 16 plt | O28: =8568+8064 -> 16632
A29: IFCO | C29: =IFERROR(INDEX('SLH Fuel Surcharge'!$H$34:$BH$64,MATCH(Collections!G29,'SLH Fuel Surcharge'!$H$34:$H$64,0),MATCH(Collections!F29,'SLH Fuel Surcharge'!$H$34:$BH$34,0)),0) -> 0 | D29: 46318 | E29: 46319 | F29: =VLOOKUP(D29,'date summary'!A:B,2,FALSE) -> 30 | I29: PO00508711 | J29: Runcton | K29: =M29/$M$1+$P29/$P$1+Q29/$Q$1+R29/$R$1+S29/$S$1+T29/$T$1+U29/$U$1+V29/$V$1+W29/$W$1+X29/$X$1+Y29/$Y$1+N29/252+O29/504+Z29/190 -> 26 | U29: 3000 | V29: 3360 | AA29: 304218888
A30: ALDI | C30: =IFERROR(INDEX('SLH Fuel Surcharge'!$H$34:$BH$64,MATCH(Collections!G30,'SLH Fuel Surcharge'!$H$34:$H$64,0),MATCH(Collections!F30,'SLH Fuel Surcharge'!$H$34:$BH$34,0)),0) -> 0 | D30: 46319 | E30: 46320 | F30: =VLOOKUP(D30,'date summary'!A:B,2,FALSE) -> 31 | H30: 228950543 | I30: PO00508354 | J30: Selsey | K30: =M30/$M$1+$P30/$P$1+Q30/$Q$1+R30/$R$1+S30/$S$1+T30/$T$1+U30/$U$1+V30/$V$1+W30/$W$1+X30/$X$1+Y30/$Y$1+N30/252+O30/504+Z30/190 -> 33 | M30: 8316
A31: ALDI | C31: =IFERROR(INDEX('SLH Fuel Surcharge'!$H$34:$BH$64,MATCH(Collections!G31,'SLH Fuel Surcharge'!$H$34:$H$64,0),MATCH(Collections!F31,'SLH Fuel Surcharge'!$H$34:$BH$34,0)),0) -> 0 | D31: 46319 | E31: 46320 | F31: =VLOOKUP(D31,'date summary'!A:B,2,FALSE) -> 31 | H31: 228950651 | I31: PO00508360 | J31: Merston / Runcton | K31: =M31/$M$1+$P31/$P$1+Q31/$Q$1+R31/$R$1+S31/$S$1+T31/$T$1+U31/$U$1+V31/$V$1+W31/$W$1+X31/$X$1+Y31/$Y$1+N31/252+O31/504+Z31/190 -> 33 | L31: Merston 13 plt / Runcton 20 plt | M31: 8316
A32: JS | B32: PO00508794 | C32: =IFERROR(INDEX('SLH Fuel Surcharge'!$H$34:$BH$64,MATCH(Collections!G32,'SLH Fuel Surcharge'!$H$34:$H$64,0),MATCH(Collections!F32,'SLH Fuel Surcharge'!$H$34:$BH$34,0)),0) -> 106.10128 | D32: 46319 | E32: 46320 | F32: =VLOOKUP(D32,'date summary'!A:B,2,FALSE) -> 31 | G32: Dartford | H32: NAT5464/377241 | I32: PO00508366 | J32: Runcton | K32: =M32/$M$1+$P32/$P$1+Q32/$Q$1+R32/$R$1+S32/$S$1+T32/$T$1+U32/$U$1+V32/$V$1+W32/$W$1+X32/$X$1+Y32/$Y$1+N32/252+O32/504+Z32/190 -> 26 | W32: 1820 | X32: 2880 | Y32: 660
A33: IFCO | C33: =IFERROR(INDEX('SLH Fuel Surcharge'!$H$34:$BH$64,MATCH(Collections!G33,'SLH Fuel Surcharge'!$H$34:$H$64,0),MATCH(Collections!F33,'SLH Fuel Surcharge'!$H$34:$BH$34,0)),0) -> 0 | D33: 46319 | E33: 46320 | F33: =VLOOKUP(D33,'date summary'!A:B,2,FALSE) -> 31 | I33: PO00508704 | J33: Merston | K33: =M33/$M$1+$P33/$P$1+Q33/$Q$1+R33/$R$1+S33/$S$1+T33/$T$1+U33/$U$1+V33/$V$1+W33/$W$1+X33/$X$1+Y33/$Y$1+N33/252+O33/504+Z33/190 -> 20 | L33: *Freshcut delivery for 25/10 am* | V33: 4200 | AA33: 304218870
A34: IFCO | C34: =IFERROR(INDEX('SLH Fuel Surcharge'!$H$34:$BH$64,MATCH(Collections!G34,'SLH Fuel Surcharge'!$H$34:$H$64,0),MATCH(Collections!F34,'SLH Fuel Surcharge'!$H$34:$BH$34,0)),0) -> 0 | D34: 46319 | E34: 46320 | F34: =VLOOKUP(D34,'date summary'!A:B,2,FALSE) -> 31 | I34: PO00508715 | J34: Selsey | K34: =M34/$M$1+$P34/$P$1+Q34/$Q$1+R34/$R$1+S34/$S$1+T34/$T$1+U34/$U$1+V34/$V$1+W34/$W$1+X34/$X$1+Y34/$Y$1+N34/252+O34/504+Z34/190 -> 26 | U34: 900 | V34: 4830 | AA34: 304218899
C35: =IFERROR(INDEX('SLH Fuel Surcharge'!$H$34:$BH$64,MATCH(Collections!G35,'SLH Fuel Surcharge'!$H$34:$H$64,0),MATCH(Collections!F35,'SLH Fuel Surcharge'!$H$34:$BH$34,0)),0) -> 0 | F35: =VLOOKUP(D35,'date summary'!A:B,2,FALSE) -> #N/A | K35: =M35/$M$1+$P35/$P$1+Q35/$Q$1+R35/$R$1+S35/$S$1+T35/$T$1+U35/$U$1+V35/$V$1+W35/$W$1+X35/$X$1+Y35/$Y$1+N35/252+O35/504+Z35/190 -> 0
C36: =IFERROR(INDEX('SLH Fuel Surcharge'!$H$34:$BH$64,MATCH(Collections!G36,'SLH Fuel Surcharge'!$H$34:$H$64,0),MATCH(Collections!F36,'SLH Fuel Surcharge'!$H$34:$BH$34,0)),0) -> 0 | F36: =VLOOKUP(D36,'date summary'!A:B,2,FALSE) -> #N/A | K36: =M36/$M$1+$P36/$P$1+Q36/$Q$1+R36/$R$1+S36/$S$1+T36/$T$1+U36/$U$1+V36/$V$1+W36/$W$1+X36/$X$1+Y36/$Y$1+N36/252+O36/504+Z36/190 -> 0
C37: =IFERROR(INDEX('SLH Fuel Surcharge'!$H$34:$BH$64,MATCH(Collections!G37,'SLH Fuel Surcharge'!$H$34:$H$64,0),MATCH(Collections!F37,'SLH Fuel Surcharge'!$H$34:$BH$34,0)),0) -> 0 | F37: =VLOOKUP(D37,'date summary'!A:B,2,FALSE) -> #N/A | K37: =M37/$M$1+$P37/$P$1+Q37/$Q$1+R37/$R$1+S37/$S$1+T37/$T$1+U37/$U$1+V37/$V$1+W37/$W$1+X37/$X$1+Y37/$Y$1+N37/252+O37/504+Z37/190 -> 0
C38: =IFERROR(INDEX('SLH Fuel Surcharge'!$H$34:$BH$64,MATCH(Collections!G38,'SLH Fuel Surcharge'!$H$34:$H$64,0),MATCH(Collections!F38,'SLH Fuel Surcharge'!$H$34:$BH$34,0)),0) -> 0 | F38: =VLOOKUP(D38,'date summary'!A:B,2,FALSE) -> #N/A | K38: =M38/$M$1+$P38/$P$1+Q38/$Q$1+R38/$R$1+S38/$S$1+T38/$T$1+U38/$U$1+V38/$V$1+W38/$W$1+X38/$X$1+Y38/$Y$1+N38/252+O38/504+Z38/190 -> 0
C39: =IFERROR(INDEX('SLH Fuel Surcharge'!$H$34:$BH$64,MATCH(Collections!G39,'SLH Fuel Surcharge'!$H$34:$H$64,0),MATCH(Collections!F39,'SLH Fuel Surcharge'!$H$34:$BH$34,0)),0) -> 0 | F39: =VLOOKUP(D39,'date summary'!A:B,2,FALSE) -> #N/A | K39: =M39/$M$1+$P39/$P$1+Q39/$Q$1+R39/$R$1+S39/$S$1+T39/$T$1+U39/$U$1+V39/$V$1+W39/$W$1+X39/$X$1+Y39/$Y$1+N39/252+O39/504+Z39/190 -> 0
C40: =IFERROR(INDEX('SLH Fuel Surcharge'!$H$34:$BH$64,MATCH(Collections!G40,'SLH Fuel Surcharge'!$H$34:$H$64,0),MATCH(Collections!F40,'SLH Fuel Surcharge'!$H$34:$BH$34,0)),0) -> 0 | F40: =VLOOKUP(D40,'date summary'!A:B,2,FALSE) -> #N/A | K40: =M40/$M$1+$P40/$P$1+Q40/$Q$1+R40/$R$1+S40/$S$1+T40/$T$1+U40/$U$1+V40/$V$1+W40/$W$1+X40/$X$1+Y40/$Y$1+N40/252+O40/504+Z40/190 -> 0
...

Sheet SLH Fuel Surcharge
B2: Drayton
B3: Merston | I3: 1 | J3: 2 | K3: 3 | L3: 4 | M3: 5 | N3: 6 | O3: 7 | P3: 8 | Q3: 9 | R3: 10 | S3: 11 | T3: 12 | U3: 13 | V3: 14 | W3: 15 | X3: 16 | Y3: 17 | Z3: 18 | AA3: 19 | AB3: 20 | AC3: 21 | AD3: 22 | AE3: 23 | AF3: 24 | AG3: 25 | AH3: 26 | AI3: 27 | AJ3: 28 | AK3: 29 | AL3: 30 | AM3: 31 | AN3: 32 | AO3: 33 | AP3: 34 | AQ3: 35 | AR3: 36 | AS3: 37 | AT3: 38 | AU3: 39 | AV3: 40 | AW3: 41 | AX3: 42 | AY3: 43 | AZ3: 44 | BA3: 45 | BB3: 46 | BC3: 47 | BD3: 48 | BE3: 49 | BF3: 50 | BG3: 51 | BH3: 52
B4: Runcton
B5: Selsey
H6: SLH01 | I6: =I12 -> 0.13746352 | J6: =J12 -> 0.14911944 | K6: =K12 -> 0.1538464 | L6: =L12 -> 0.15687048 | M6: =M12 -> 0.12718752 | N6: =N12 -> 0.11033488 | O6: =O12 -> 0.13482112 | P6: =P12 -> 0.12196144 | ... BH6: =BH12 -> -0.2936
H8: SLH01 | I8: ='[1]Fuel Surcharge'!I$34 -> 46109 | J8: ='[1]Fuel Surcharge'!J$34 -> 46116 | K8: ='[1]Fuel Surcharge'!K$34 -> 46123 | L8: ='[1]Fuel Surcharge'!L$34 -> 46130 | M8: ='[1]Fuel Surcharge'!M$34 -> 46137 | N8: ='[1]Fuel Surcharge'!N$34 -> 46144 | O8: ='[1]Fuel Surcharge'!O$34 -> 46151 | P8: ='[1]Fuel Surcharge'!P$34 -> 46158 | ... V8: ='[1]Fuel Surcharge'!V$34 -> 46200 | W8: ='[2]Fuel Surcharge'!J$34 -> 46207 | X8: ='[2]Fuel Surcharge'!K$34 -> 46214 | Y8: ='[2]Fuel Surcharge'!L$34 -> 46221 | Z8: ='[2]Fuel Surcharge'!M$34 -> 46228 | AA8: ='[2]Fuel Surcharge'!N$34 -> 46235 | AB8: ='[2]Fuel Surcharge'!O$34 -> 46242 | AC8: ='[2]Fuel Surcharge'!P$34 -> 46249 | AD8: ='[2]Fuel Surcharge'!Q$34 -> 46256 | ... BM8: ='[2]Fuel Surcharge'!AZ$34 -> 46501
H9: Fuel Price | I9: ='[1]Fuel Surcharge'!I$35 -> 146.82 | J9: ='[1]Fuel Surcharge'!J$35 -> 150.79 | K9: ='[1]Fuel Surcharge'!K$35 -> 152.4 | L9: ='[1]Fuel Surcharge'!L$35 -> 153.43 | M9: ='[1]Fuel Surcharge'!M$35 -> 143.32 | N9: ='[1]Fuel Surcharge'!N$35 -> 137.58 | O9: ='[1]Fuel Surcharge'!O$35 -> 145.92 | P9: ='[1]Fuel Surcharge'!P$35 -> 141.54 | ... V9: ='[1]Fuel Surcharge'!V$35 -> 125.81 | W9: ='[2]Fuel Surcharge'!J$35 -> 125 | X9: ='[2]Fuel Surcharge'!K$35 -> 126 | Y9: ='[2]Fuel Surcharge'!L$35 -> 130.75 | Z9: ='[2]Fuel Surcharge'!M$35 -> 129.95 | AA9: ='[2]Fuel Surcharge'!N$35 -> 137.53 | AB9: ='[2]Fuel Surcharge'!O$35 -> 145.1 | AC9: ='[2]Fuel Surcharge'!P$35 -> 147.08 | AD9: ='[2]Fuel Surcharge'!Q$35 -> 142.06 | ... BM9: ='[2]Fuel Surcharge'!AZ$35 -> 0
H10: Base Price | I10: ='[1]Fuel Surcharge'!I$36 -> 100 | J10: ='[1]Fuel Surcharge'!J$36 -> 100 | K10: ='[1]Fuel Surcharge'!K$36 -> 100 | L10: ='[1]Fuel Surcharge'!L$36 -> 100 | M10: ='[1]Fuel Surcharge'!M$36 -> 100 | N10: ='[1]Fuel Surcharge'!N$36 -> 100 | O10: ='[1]Fuel Surcharge'!O$36 -> 100 | P10: ='[1]Fuel Surcharge'!P$36 -> 100 | ... V10: ='[1]Fuel Surcharge'!V$36 -> 100 | W10: ='[2]Fuel Surcharge'!W$36 -> 100 | X10: ='[2]Fuel Surcharge'!X$36 -> 100 | Y10: ='[2]Fuel Surcharge'!Y$36 -> 100 | Z10: ='[2]Fuel Surcharge'!Z$36 -> 100 | AA10: ='[2]Fuel Surcharge'!AA$36 -> 100 | AB10: ='[2]Fuel Surcharge'!AB$36 -> 100 | AC10: ='[2]Fuel Surcharge'!AC$36 -> 100 | AD10: ='[2]Fuel Surcharge'!AD$36 -> 100 | ... BM10: ='[2]Fuel Surcharge'!BM$36 -> 0
H11: Operating % | I11: ='[1]Fuel Surcharge'!I$37 -> 0.2936 | J11: ='[1]Fuel Surcharge'!J$37 -> 0.2936 | K11: ='[1]Fuel Surcharge'!K$37 -> 0.2936 | L11: ='[1]Fuel Surcharge'!L$37 -> 0.2936 | M11: ='[1]Fuel Surcharge'!M$37 -> 0.2936 | N11: ='[1]Fuel Surcharge'!N$37 -> 0.2936 | O11: ='[1]Fuel Surcharge'!O$37 -> 0.2936 | P11: ='[1]Fuel Surcharge'!P$37 -> 0.2936 | ... V11: ='[1]Fuel Surcharge'!V$37 -> 0.2936 | W11: ='[2]Fuel Surcharge'!W$37 -> 0.2936 | X11: ='[2]Fuel Surcharge'!X$37 -> 0.2936 | Y11: ='[2]Fuel Surcharge'!Y$37 -> 0.2936 | Z11: ='[2]Fuel Surcharge'!Z$37 -> 0.2936 | AA11: ='[2]Fuel Surcharge'!AA$37 -> 0.2936 | AB11: ='[2]Fuel Surcharge'!AB$37 -> 0.2936 | AC11: ='[2]Fuel Surcharge'!AC$37 -> 0.2936 | AD11: ='[2]Fuel Surcharge'!AD$37 -> 0.2936 | ... BM11: ='[2]Fuel Surcharge'!BM$37 -> 0
H12: Fuel Surcharge | I12: =((I9-I10)*I11)/I10 -> 0.13746352 | J12: =((J9-J10)*J11)/J10 -> 0.14911944 | K12: =((K9-K10)*K11)/K10 -> 0.1538464 | L12: =((L9-L10)*L11)/L10 -> 0.15687048 | M12: =((M9-M10)*M11)/M10 -> 0.12718752 | N12: =((N9-N10)*N11)/N10 -> 0.11033488 | O12: =((O9-O10)*O11)/O10 -> 0.13482112 | P12: =((P9-P10)*P11)/P10 -> 0.12196144 | ... BM12: =((BM9-BM10)*BM11)/BM10 -> #DIV/0!
H13: Wk No | I13: 1 | J13: 2 | K13: 3 | L13: 4 | M13: 5 | N13: 6 | O13: 7 | P13: 8 | Q13: 9 | R13: 10 | S13: 11 | T13: 12 | U13: 13 | V13: 14 | W13: 15 | X13: 16 | Y13: 17 | Z13: 18 | AA13: 19 | AB13: 20 | AC13: 21 | AD13: 22 | AE13: 23 | AF13: 24 | AG13: 25 | AH13: 26 | AI13: 27 | AJ13: 28 | AK13: 29 | AL13: 30 | AM13: 31 | AN13: 32 | AO13: 33 | AP13: 34 | AQ13: 35 | AR13: 36 | AS13: 37 | AT13: 38 | AU13: 39 | AV13: 40 | AW13: 41 | AX13: 42 | AY13: 43 | AZ13: 44 | BA13: 45 | BB13: 46 | BC13: 47 | BD13: 48 | BE13: 49 | BF13: 50 | BG13: 51 | BH13: 52 | BI13: 53 | BJ13: 53 | BK13: 53 | BL13: 53 | BM13: 53
F14: Wk No | G14: 1 | H14: Inbound | I14: #VALUE! | J14: #VALUE! | K14: #VALUE! | L14: #VALUE! | M14: #VALUE! | N14: #VALUE! | O14: #VALUE! | P14: #VALUE! | Q14: #VALUE! | R14: #VALUE! | S14: #VALUE! | T14: #VALUE! | U14: #VALUE! | V14: #VALUE! | W14: #VALUE! | X14: #VALUE! | Y14: #VALUE! | Z14: #VALUE! | AA14: #VALUE! | AB14: #VALUE! | AC14: #VALUE! | AD14: #VALUE! | AE14: #VALUE! | AF14: #VALUE! | AG14: #VALUE! | AH14: #VALUE! | AI14: #VALUE! | AJ14: #VALUE! | AK14: #VALUE! | AL14: #VALUE! | AM14: #VALUE! | AN14: #VALUE! | AO14: #VALUE! | AP14: #VALUE! | AQ14: #VALUE! | AR14: #VALUE! | AS14: #VALUE! | AT14: #VALUE! | AU14: #VALUE! | AV14: #VALUE! | AW14: #VALUE! | AX14: #VALUE! | AY14: #VALUE! | AZ14: #VALUE! | BA14: #VALUE! | BB14: #VALUE! | BC14: #VALUE! | BD14: #VALUE! | BE14: #VALUE! | BF14: #VALUE! | BG14: #VALUE! | BH14: #VALUE! | BI14: #VALUE! | BJ14: #VALUE! | BK14: #VALUE! | BL14: #VALUE! | BM14: #VALUE!
F15: BRO06 | G15: 0 | H15: Crate Returns | I15: #VALUE! | J15: #VALUE! | K15: #VALUE! | L15: #VALUE! | M15: #VALUE! | N15: #VALUE! | O15: #VALUE! | P15: #VALUE! | Q15: #VALUE! | R15: #VALUE! | S15: #VALUE! | T15: #VALUE! | U15: #VALUE! | V15: #VALUE! | W15: #VALUE! | X15: #VALUE! | Y15: #VALUE! | Z15: #VALUE! | AA15: #VALUE! | AB15: #VALUE! | AC15: #VALUE! | AD15: #VALUE! | AE15: #VALUE! | AF15: #VALUE! | AG15: #VALUE! | AH15: #VALUE! | AI15: #VALUE! | AJ15: #VALUE! | AK15: #VALUE! | AL15: #VALUE! | AM15: #VALUE! | AN15: #VALUE! | AO15: #VALUE! | AP15: #VALUE! | AQ15: #VALUE! | AR15: #VALUE! | AS15: #VALUE! | AT15: #VALUE! | AU15: #VALUE! | AV15: #VALUE! | AW15: #VALUE! | AX15: #VALUE! | AY15: #VALUE! | AZ15: #VALUE! | BA15: #VALUE! | BB15: #VALUE! | BC15: #VALUE! | BD15: #VALUE! | BE15: #VALUE! | BF15: #VALUE! | BG15: #VALUE! | BH15: #VALUE! | BI15: #VALUE! | BJ15: #VALUE! | BK15: #VALUE! | BL15: #VALUE! | BM15: #VALUE!
F16: COC01 | G16: 0 | H16: Fuel Surcharge | I16: =SUM(I$14+I$15)*I$12 -> #VALUE! | J16: =SUM(J$14+J$15)*J$12 -> #VALUE! | K16: =SUM(K$14+K$15)*K$12 -> #VALUE! | L16: =SUM(L$14+L$15)*L$12 -> #VALUE! | M16: =SUM(M$14+M$15)*M$12 -> #VALUE! | N16: =SUM(N$14+N$15)*N$12 -> #VALUE! | O16: =SUM(O$14+O$15)*O$12 -> #VALUE! | P16: =SUM(P$14+P$15)*P$12 -> #VALUE! | ... BM16: =SUM(BM$14+BM$15)*BM$12 -> #VALUE!
F17: COL06 | G17: 0 | H17: Total Spend | I17: =SUM(I14:I16) -> #VALUE! | J17: =SUM(J14:J16) -> #VALUE! | K17: =SUM(K14:K16) -> #VALUE! | L17: =SUM(L14:L16) -> #VALUE! | M17: =SUM(M14:M16) -> #VALUE! | N17: =SUM(N14:N16) -> #VALUE! | O17: =SUM(O14:O16) -> #VALUE! | P17: =SUM(P14:P16) -> #VALUE! | ... BM17: =SUM(BM14:BM16) -> #VALUE!
F18: COO10 | G18: 0 | H18: 0 | I18: 0 | J18: 0 | K18: 0 | L18: 0 | M18: 0 | N18: 0 | O18: 0 | P18: 0 | Q18: 0 | R18: 0 | S18: 0 | T18: 0 | U18: 0 | V18: 0 | W18: 0 | X18: 0 | Y18: 0 | Z18: 0 | AA18: 0 | AB18: 0 | AC18: 0 | AD18: 0 | AE18: 0 | AF18: 0 | AG18: 0 | AH18: 0 | AI18: 0 | AJ18: 0 | AK18: 0 | AL18: 0 | AM18: 0 | AN18: 0 | AO18: 0 | AP18: 0 | AQ18: 0 | AR18: 0 | AS18: 0 | AT18: 0 | AU18: 0 | AV18: 0 | AW18: 0 | AX18: 0 | AY18: 0 | AZ18: 0 | BA18: 0 | BB18: 0 | BC18: 0 | BD18: 0 | BE18: 0 | BF18: 0 | BG18: 0
F19: ERS01 | G19: 0 | H19: 0 | I19: 0 | J19: 0 | K19: 0 | L19: 0 | M19: 0 | N19: 0 | O19: 0 | P19: 0 | Q19: 0 | R19: 0 | S19: 0 | T19: 0 | U19: 0 | V19: 0 | W19: 0 | X19: 0 | Y19: 0 | Z19: 0 | AA19: 0 | AB19: 0 | AC19: 0 | AD19: 0 | AE19: 0 | AF19: 0 | AG19: 0 | AH19: 0 | AI19: 0 | AJ19: 0 | AK19: 0 | AL19: 0 | AM19: 0 | AN19: 0 | AO19: 0 | AP19: 0 | AQ19: 0 | AR19: 0 | AS19: 0 | AT19: 0 | AU19: 0 | AV19: 0 | AW19: 0 | AX19: 0 | AY19: 0 | AZ19: 0 | BA19: 0 | BB19: 0 | BC19: 0 | BD19: 0 | BE19: 0 | BF19: 0 | BG19: 0
F20: EUR06 | G20: 0 | H20: 0 | I20: 0 | J20: 0 | K20: 0 | L20: 0 | M20: 0 | N20: 0 | O20: 0 | P20: 0 | Q20: 0 | R20: 0 | S20: 0 | T20: 0 | U20: 0 | V20: 0 | W20: 0 | X20: 0 | Y20: 0 | Z20: 0 | AA20: 0 | AB20: 0 | AC20: 0 | AD20: 0 | AE20: 0 | AF20: 0 | AG20: 0 | AH20: 0 | AI20: 0 | AJ20: 0 | AK20: 0 | AL20: 0 | AM20: 0 | AN20: 0 | AO20: 0 | AP20: 0 | AQ20: 0 | AR20: 0 | AS20: 0 | AT20: 0 | AU20: 0 | AV20: 0 | AW20: 0 | AX20: 0 | AY20: 0 | AZ20: 0 | BA20: 0 | BB20: 0 | BC20: 0 | BD20: 0 | BE20: 0 | BF20: 0 | BG20: 0
F21: ICE02 | G21: 0 | H21: 0 | I21: 0 | J21: 0 | K21: 0 | L21: 0 | M21: 0 | N21: 0 | O21: 0 | P21: 0 | Q21: 0 | R21: 0 | S21: 0 | T21: 0 | U21: 0 | V21: 0 | W21: 0 | X21: 0 | Y21: 0 | Z21: 0 | AA21: 0 | AB21: 0 | AC21: 0 | AD21: 0 | AE21: 0 | AF21: 0 | AG21: 0 | AH21: 0 | AI21: 0 | AJ21: 0 | AK21: 0 | AL21: 0 | AM21: 0 | AN21: 0 | AO21: 0 | AP21: 0 | AQ21: 0 | AR21: 0 | AS21: 0 | AT21: 0 | AU21: 0 | AV21: 0 | AW21: 0 | AX21: 0 | AY21: 0 | AZ21: 0 | BA21: 0 | BB21: 0 | BC21: 0 | BD21: 0 | BE21: 0 | BF21: 0 | BG21: 0
F22: JOH11 | G22: 0 | H22: 0 | I22: 0 | J22: 0 | K22: 0 | L22: 0 | M22: 0 | N22: 0 | O22: 0 | P22: 0 | Q22: 0 | R22: 0 | S22: 0 | T22: 0 | U22: 0 | V22: 0 | W22: 0 | X22: 0 | Y22: 0 | Z22: 0 | AA22: 0 | AB22: 0 | AC22: 0 | AD22: 0 | AE22: 0 | AF22: 0 | AG22: 0 | AH22: 0 | AI22: 0 | AJ22: 0 | AK22: 0 | AL22: 0 | AM22: 0 | AN22: 0 | AO22: 0 | AP22: 0 | AQ22: 0 | AR22: 0 | AS22: 0 | AT22: 0 | AU22: 0 | AV22: 0 | AW22: 0 | AX22: 0 | AY22: 0 | AZ22: 0 | BA22: 0 | BB22: 0 | BC22: 0 | BD22: 0 | BE22: 0 | BF22: 0 | BG22: 0
F23: MAS01 | G23: 0 | H23: 0 | I23: 0 | J23: 0 | K23: 0 | L23: 0 | M23: 0 | N23: 0 | O23: 0 | P23: 0 | Q23: 0 | R23: 0 | S23: 0 | T23: 0 | U23: 0 | V23: 0 | W23: 0 | X23: 0 | Y23: 0 | Z23: 0 | AA23: 0 | AB23: 0 | AC23: 0 | AD23: 0 | AE23: 0 | AF23: 0 | AG23: 0 | AH23: 0 | AI23: 0 | AJ23: 0 | AK23: 0 | AL23: 0 | AM23: 0 | AN23: 0 | AO23: 0 | AP23: 0 | AQ23: 0 | AR23: 0 | AS23: 0 | AT23: 0 | AU23: 0 | AV23: 0 | AW23: 0 | AX23: 0 | AY23: 0 | AZ23: 0 | BA23: 0 | BB23: 0 | BC23: 0 | BD23: 0 | BE23: 0 | BF23: 0 | BG23: 0
F24: MAT06 | G24: 0 | H24: 0 | I24: 0 | J24: 0 | K24: 0 | L24: 0 | M24: 0 | N24: 0 | O24: 0 | P24: 0 | Q24: 0 | R24: 0 | S24: 0 | T24: 0 | U24: 0 | V24: 0 | W24: 0 | X24: 0 | Y24: 0 | Z24: 0 | AA24: 0 | AB24: 0 | AC24: 0 | AD24: 0 | AE24: 0 | AF24: 0 | AG24: 0 | AH24: 0 | AI24: 0 | AJ24: 0 | AK24: 0 | AL24: 0 | AM24: 0 | AN24: 0 | AO24: 0 | AP24: 0 | AQ24: 0 | AR24: 0 | AS24: 0 | AT24: 0 | AU24: 0 | AV24: 0 | AW24: 0 | AX24: 0 | AY24: 0 | AZ24: 0 | BA24: 0 | BB24: 0 | BC24: 0 | BD24: 0 | BE24: 0 | BF24: 0 | BG24: 0
F25: PAU03 | G25: 0 | H25: 0 | I25: 0 | J25: 0 | K25: 0 | L25: 0 | M25: 0 | N25: 0 | O25: 0 | P25: 0 | Q25: 0 | R25: 0 | S25: 0 | T25: 0 | U25: 0 | V25: 0 | W25: 0 | X25: 0 | Y25: 0 | Z25: 0 | AA25: 0 | AB25: 0 | AC25: 0 | AD25: 0 | AE25: 0 | AF25: 0 | AG25: 0 | AH25: 0 | AI25: 0 | AJ25: 0 | AK25: 0 | AL25: 0 | AM25: 0 | AN25: 0 | AO25: 0 | AP25: 0 | AQ25: 0 | AR25: 0 | AS25: 0 | AT25: 0 | AU25: 0 | AV25: 0 | AW25: 0 | AX25: 0 | AY25: 0 | AZ25: 0 | BA25: 0 | BB25: 0 | BC25: 0 | BD25: 0 | BE25: 0 | BF25: 0 | BG25: 0
F26: PIC01 | G26: 0 | H26: 0 | I26: 0 | J26: 0 | K26: 0 | L26: 0 | M26: 0 | N26: 0 | O26: 0 | P26: 0 | Q26: 0 | R26: 0 | S26: 0 | T26: 0 | U26: 0 | V26: 0 | W26: 0 | X26: 0 | Y26: 0 | Z26: 0 | AA26: 0 | AB26: 0 | AC26: 0 | AD26: 0 | AE26: 0 | AF26: 0 | AG26: 0 | AH26: 0 | AI26: 0 | AJ26: 0 | AK26: 0 | AL26: 0 | AM26: 0 | AN26: 0 | AO26: 0 | AP26: 0 | AQ26: 0 | AR26: 0 | AS26: 0 | AT26: 0 | AU26: 0 | AV26: 0 | AW26: 0 | AX26: 0 | AY26: 0 | AZ26: 0 | BA26: 0 | BB26: 0 | BC26: 0 | BD26: 0 | BE26: 0 | BF26: 0 | BG26: 0
F27: PIC03 | G27: 0 | H27: 0 | I27: 0 | J27: 0 | K27: 0 | L27: 0 | M27: 0 | N27: 0 | O27: 0 | P27: 0 | Q27: 0 | R27: 0 | S27: 0 | T27: 0 | U27: 0 | V27: 0 | W27: 0 | X27: 0 | Y27: 0 | Z27: 0 | AA27: 0 | AB27: 0 | AC27: 0 | AD27: 0 | AE27: 0 | AF27: 0 | AG27: 0 | AH27: 0 | AI27: 0 | AJ27: 0 | AK27: 0 | AL27: 0 | AM27: 0 | AN27: 0 | AO27: 0 | AP27: 0 | AQ27: 0 | AR27: 0 | AS27: 0 | AT27: 0 | AU27: 0 | AV27: 0 | AW27: 0 | AX27: 0 | AY27: 0 | AZ27: 0 | BA27: 0 | BB27: 0 | BC27: 0 | BD27: 0 | BE27: 0 | BF27: 0 | BG27: 0
F28: ROB05 | G28: 0 | H28: 0 | I28: 0 | J28: 0 | K28: 0 | L28: 0 | M28: 0 | N28: 0 | O28: 0 | P28: 0 | Q28: 0 | R28: 0 | S28: 0 | T28: 0 | U28: 0 | V28: 0 | W28: 0 | X28: 0 | Y28: 0 | Z28: 0 | AA28: 0 | AB28: 0 | AC28: 0 | AD28: 0 | AE28: 0 | AF28: 0 | AG28: 0 | AH28: 0 | AI28: 0 | AJ28: 0 | AK28: 0 | AL28: 0 | AM28: 0 | AN28: 0 | AO28: 0 | AP28: 0 | AQ28: 0 | AR28: 0 | AS28: 0 | AT28: 0 | AU28: 0 | AV28: 0 | AW28: 0 | AX28: 0 | AY28: 0 | AZ28: 0 | BA28: 0 | BB28: 0 | BC28: 0 | BD28: 0 | BE28: 0 | BF28: 0 | BG28: 0
F29: SLH01 | G29: 0 | H29: 0 | I29: 0 | J29: 0 | K29: 0 | L29: 0 | M29: 0 | N29: 0 | O29: 0 | P29: 0 | Q29: 0 | R29: 0 | S29: 0 | T29: 0 | U29: 0 | V29: 0 | W29: 0 | X29: 0 | Y29: 0 | Z29: 0 | AA29: 0 | AB29: 0 | AC29: 0 | AD29: 0 | AE29: 0 | AF29: 0 | AG29: 0 | AH29: 0 | AI29: 0 | AJ29: 0 | AK29: 0 | AL29: =AL$6 -> 0.1641224 | AM29: =AM$6 -> -0.2936 | AN29: =AN$6 -> -0.2936 | AO29: =AO$6 -> -0.2936 | AP29: =AP$6 -> -0.2936 | AQ29: =AQ$6 -> -0.2936 | AR29: =AR$6 -> -0.2936 | AS29: =AS$6 -> -0.2936 | ... BG29: =BG$6 -> -0.2936
F30: TON01 | G30: 0 | H30: 0 | I30: 0 | J30: 0 | K30: 0 | L30: 0 | M30: 0 | N30: 0 | O30: 0 | P30: 0 | Q30: 0 | R30: 0 | S30: 0 | T30: 0 | U30: 0 | V30: 0 | W30: 0 | X30: 0 | Y30: 0 | Z30: 0 | AA30: 0 | AB30: 0 | AC30: 0 | AD30: 0 | AE30: 0 | AF30: 0 | AG30: 0 | AH30: 0 | AI30: 0 | AJ30: 0 | AK30: 0 | AL30: 0 | AM30: 0 | AN30: 0 | AO30: 0 | AP30: 0 | AQ30: 0 | AR30: 0 | AS30: 0 | AT30: 0 | AU30: 0 | AV30: 0 | AW30: 0 | AX30: 0 | AY30: 0 | AZ30: 0 | BA30: 0 | BB30: 0 | BC30: 0 | BD30: 0 | BE30: 0 | BF30: 0 | BG30: 0
B33: Inbound
B34: Supplier code | C34: Supplier | D34: Haulier | E34: Reference | F34: Cost | H34: Depot | I34: 1 | J34: 2 | K34: 3 | L34: 4 | M34: 5 | N34: 6 | O34: 7 | P34: 8 | Q34: 9 | R34: 10 | S34: 11 | T34: 12 | U34: 13 | V34: 14 | W34: 15 | X34: 16 | Y34: 17 | Z34: 18 | AA34: 19 | AB34: 20 | AC34: 21 | AD34: 22 | AE34: 23 | AF34: 24 | AG34: 25 | AH34: 26 | AI34: 27 | AJ34: 28 | AK34: 29 | AL34: 30 | AM34: 31 | AN34: 32 | AO34: 33 | AP34: 34 | AQ34: 35 | AR34: 36 | AS34: 37 | AT34: 38 | AU34: 39 | AV34: 40 | AW34: 41 | AX34: 42 | AY34: 43 | AZ34: 44 | BA34: 45 | BB34: 46 | BC34: 47 | BD34: 48 | BE34: 49 | BF34: 50 | BG34: 51 | BH34: 52 | BI34: 53 | BJ34: 54 | BK34: 55 | BL34: 56 | BM34: 57 | BN34: 58
B35: Basingstoke | C35: SAI01 | D35: SLH01 | E35: Basingstoke | F35: 150.2 | H35: Basingstoke | I35: =($F35*$I$12)+$F35 -> 170.84702 | J35: =($F35*J$12)+$F35 -> 172.59774 | K35: =($F35*K$12)+$F35 -> 173.30773 | L35: =($F35*L$12)+$F35 -> 173.76195 | M35: =($F35*M$12)+$F35 -> 169.30357 | N35: =($F35*N$12)+$F35 -> 166.7723 | O35: =($F35*O$12)+$F35 -> 170.45013 | P35: =($F35*P$12)+$F35 -> 168.51861 | Q35: =($F35*Q$12)+$F35 -> 167.50434 | ... BM35: =($F35*BM$12)+$F35 -> #DIV/0!
B36: Emerald Park | C36: SAI01 | D36: SLH01 | E36: Emerald Park | F36: 369.72 | H36: Emerald Park | I36: =(F36*$I$12)+$F36 -> 420.54301 | J36: =($F36*J$12)+$F36 -> 424.85244 | K36: =($F36*K$12)+$F36 -> 426.60009 | L36: =($F36*L$12)+$F36 -> 427.71815 | M36: =($F36*M$12)+$F36 -> 416.74377 | N36: =($F36*N$12)+$F36 -> 410.51301 | O36: =($F36*O$12)+$F36 -> 419.56606 | P36: =($F36*P$12)+$F36 -> 414.81158 | Q36: =($F36*Q$12)+$F36 -> 412.31494 | ... BM36: =($F36*BM$12)+$F36 -> #DIV/0!
B37: Dartford | C37: SAI01 | D37: SLH01 | E37: Dartford | F37: 150.2 | H37: Dartford | I37: =(F37*$I$12)+$F37 -> 170.84702 | J37: =($F37*J$12)+$F37 -> 172.59774 | K37: =($F37*K$12)+$F37 -> 173.30773 | L37: =($F37*L$12)+$F37 -> 173.76195 | M37: =($F37*M$12)+$F37 -> 169.30357 | N37: =($F37*N$12)+$F37 -> 166.7723 | O37: =($F37*O$12)+$F37 -> 170.45013 | P37: =($F37*P$12)+$F37 -> 168.51861 | Q37: =($F37*Q$12)+$F37 -> 167.50434 | ... BM37: =($F37*BM$12)+$F37 -> #DIV/0!
B38: Waltham Point RRU | C38: SAI01 | D38: SLH01 | E38: Waltham Point RRU | F38: 196.41 | H38: Waltham Point RRU | I38: =(F38*$I$12)+$F38 -> 223.40921 | J38: =($F38*J$12)+$F38 -> 225.69855 | K38: =($F38*K$12)+$F38 -> 226.62697 | L38: =($F38*L$12)+$F38 -> 227.22093 | M38: =($F38*M$12)+$F38 -> 221.3909 | N38: =($F38*N$12)+$F38 -> 218.08087 | O38: =($F38*O$12)+$F38 -> 222.89022 | P38: =($F38*P$12)+$F38 -> 220.36445 | Q38: =($F38*Q$12)+$F38 -> 219.03813 | ... BM38: =($F38*BM$12)+$F38 -> #DIV/0!
B39: Northampton | C39: SAI01 | D39: SLH01 | E39: Northampton | F39: 335.06 | H39: Northampton | I39: =(F39*$I$12)+$F39 -> 381.11853 | J39: =($F39*J$12)+$F39 -> 385.02396 | K39: =($F39*K$12)+$F39 -> 386.60777 | L39: =($F39*L$12)+$F39 -> 387.62102 | M39: =($F39*M$12)+$F39 -> 377.67545 | N39: =($F39*N$12)+$F39 -> 372.0288 | O39: =($F39*O$12)+$F39 -> 380.23316 | P39: =($F39*P$12)+$F39 -> 375.9244 | Q39: =($F39*Q$12)+$F39 -> 373.66181 | ... BM39: =($F39*BM$12)+$F39 -> #DIV/0!
B40: Hams Hall | C40: SAI01 | D40: SLH01 | E40: Hams Hall | F40: 306.16 | H40: Hams Hall | I40: =(F40*$I$12)+$F40 -> 348.24583 | J40: =($F40*J$12)+$F40 -> 351.81441 | K40: =($F40*K$12)+$F40 -> 353.26161 | L40: =($F40*L$12)+$F40 -> 354.18747 | M40: =($F40*M$12)+$F40 -> 345.09973 | N40: =($F40*N$12)+$F40 -> 339.94013 | O40: =($F40*O$12)+$F40 -> 347.43683 | P40: =($F40*P$12)+$F40 -> 343.49971 | Q40: =($F40*Q$12)+$F40 -> 341.43228 | ... BM40: =($F40*BM$12)+$F40 -> #DIV/0!
B41: Haydock | C41: SAI01 | D41: SLH01 | E41: Haydock | H41: Haydock | I41: =(F41*$I$12)+$F41 -> 0 | J41: =($F41*J$12)+$F41 -> 0 | K41: =($F41*K$12)+$F41 -> 0 | L41: =($F41*L$12)+$F41 -> 0 | M41: =($F41*M$12)+$F41 -> 0 | N41: =($F41*N$12)+$F41 -> 0 | O41: =($F41*O$12)+$F41 -> 0 | P41: =($F41*P$12)+$F41 -> 0 | Q41: =($F41*Q$12)+$F41 -> 0 | ... BM41: =($F41*BM$12)+$F41 -> #DIV/0!
B42: Sherburn and; | C42: SAI01 | D42: SLH01 | E42: Sherburn and; | F42: 438.23 | H42: Sherburn and; | I42: =(F42*$I$12)+$F42 -> 498.47064 | J42: =($F42*J$12)+$F42 -> 503.57861 | K42: =($F42*K$12)+$F42 -> 505.65011 | L42: =($F42*L$12)+$F42 -> 506.97535 | M42: =($F42*M$12)+$F42 -> 493.96739 | N42: =($F42*N$12)+$F42 -> 486.58205 | O42: =($F42*O$12)+$F42 -> 497.31266 | P42: =($F42*P$12)+$F42 -> 491.67716 | Q42: =($F42*Q$12)+$F42 -> 488.71788 | ... BM42: =($F42*BM$12)+$F42 -> #DIV/0!
B43: Langland’s Park | C43: SAI01 | D43: SLH01 | E43: Langland’s Park | H43: Langland’s Park | I43: =(F43*$I$12)+$F43 -> 0 | J43: =($F43*J$12)+$F43 -> 0 | K43: =($F43*K$12)+$F43 -> 0 | L43: =($F43*L$12)+$F43 -> 0 | M43: =($F43*M$12)+$F43 -> 0 | N43: =($F43*N$12)+$F43 -> 0 | O43: =($F43*O$12)+$F43 -> 0 | P43: =($F43*P$12)+$F43 -> 0 | Q43: =($F43*Q$12)+$F43 -> 0 | ... BM43: =($F43*BM$12)+$F43 -> #DIV/0!
B44: WAKEFIELD & FRESHCUT | C44: IFC02 | D44: SLH01 | E44: WAKEFIELD & FRESHCUT | F44: 485.26 | H44: WAKEFIELD & FRESHCUT | I44: =(F44*$I$12)+$F44 -> 551.96555 | J44: =($F44*J$12)+$F44 -> 557.6217 | K44: =($F44*K$12)+$F44 -> 559.9155 | L44: =($F44*L$12)+$F44 -> 561.38297 | M44: =($F44*M$12)+$F44 -> 546.97902 | N44: =($F44*N$12)+$F44 -> 538.8011 | O44: =($F44*O$12)+$F44 -> 550.6833 | P44: =($F44*P$12)+$F44 -> 544.44301 | Q44: =($F44*Q$12)+$F44 -> 541.16614 | ... BM44: =($F44*BM$12)+$F44 -> #DIV/0!
...

Sheet date summary
A1: 46109 | B1: 1
A2: 46110 | B2: 1
A3: 46111 | B3: 1
A4: 46112 | B4: 1
A5: 46113 | B5: 1
A6: 46114 | B6: 1
A7: 46115 | B7: 1
A8: 46116 | B8: =B1+1 -> 2
A9: 46117 | B9: =B2+1 -> 2
A10: 46118 | B10: =B3+1 -> 2
A11: 46119 | B11: =B4+1 -> 2
A12: 46120 | B12: =B5+1 -> 2
A13: 46121 | B13: =B6+1 -> 2
A14: 46122 | B14: =B7+1 -> 2
A15: 46123 | B15: =B8+1 -> 3
A16: 46124 | B16: =B9+1 -> 3
A17: 46125 | B17: =B10+1 -> 3
A18: 46126 | B18: =B11+1 -> 3
A19: 46127 | B19: =B12+1 -> 3
... A54: 46162 | B54: =B47+1 -> 8
A55: 46163 | B55: 8
A56: 46164 | B56: 8
A57: 46165 | B57: 9
A58: 46166 | B58: 9
A59: 46167 | B59: 9
A60: 46168 | B60: 9
A61: 46169 | B61: 9
A62: 46170 | B62: 9
A63: 46171 | B63: 9
A64: 46172 | B64: 10
A65: 46173 | B65: 10
A66: 46174 | B66: 10
... A126: 46234 | B126: 18
A127: 46235 | B127: =B120+1 -> 19
A128: 46236 | B128: =B121+1 -> 19
A129: 46237 | B129: =B122+1 -> 19
A130: 46238 | B130: =B123+1 -> 19
A131: 46239 | B131: =B124+1 -> 19
A132: 46240 | B132: =B125+1 -> 19
A133: 46241 | B133: =B126+1 -> 19
...

Sheet Sheet1

Sheet Charges
A2: SAINSBURYS | B2: Collection depot | C2: cost | D2: new rate 06.11.2021
B4: Basingstoke | C4: 130 | D4: 136.87 | E4: 19JSCRATE*
B5: Emerald Park, Bristol | C5: 320 | D5: 336.91 | E5: 19JSCRATE*
B6: Dartford | C6: 130 | D6: 136.87 | E6: 19JSCRATE*
B7: Waltham Point, Waltham Abbey | C7: 170 | D7: 178.98 | E7: 19JSCRATE*
B8: Northampton | C8: 290 | D8: 305.33 | E8: 19JSCRATE*
B9: Hams Hall | C9: 290 | E9: 19JSCRATE*
B10: Haydock | C10: 380 | E10: 19JSCRATE*
B11: Sherburn and; | C11: 390 | D11: 410.61 | E11: 19JSCRATE*
B12: Langland’s Park | C12: 690 | E12: 19JSCRATE*
A15: IFCO | B15: new rate 01 May - 2023
B17: WAKEFIELD & FRESHCUT | C17: 457.13 | D17: 19MORCRAT*
B18: WAKEFIELD | C18: 408.15 | D18: 19MORCRAT*
B19: NUNEATON | C19: 299.31 | D19: 19MORCRAT*
B20: Wellingborough | C20: 270.38 | D20: 19MORCRAT*
B21: Warrington | C21: 408.15 | D21: 19MORCRAT*
B22: Milton Keynes | C22: 261.21 | D22: 19MORCRAT*
B23: Glasshoughton | C23: 462.64 | D23: 19MORCRAT*
A27: ALDI | B27: Collection depot | C27: cost | E27: Deposit
B28: Doncaster | C28: 408.15 | D28: 19ALDCRATE* | E28: 3151.76
B29: Tamworth | C29: 288.36 | D29: 19ALDCRATE* | E29: 3151.76
A30: Eur14 | B30: Bedford | C30: 252.68 | D30: 19ALDCRATE* | E30: 3151.76
A33: TESCO | B33: Collection depot | C33: cost | D33: 19TESCRATE*
B34: confirmed at the time
A36: Doncaster £408.15
A37: Avonmouth £424.48 | C37: IPL Hull £587.74
A38: Snodland £310.20 | C38: IPL Tamworth £288.42
A39: Peterborough £457.13
A40: Hinckley £408.15
A41: Southampton £185.02
A42: Dagenham £310.20
A43: Didcot £299.31
A44: Widnes £587.74
A45: Dartford £141.49
